Workbook

Sheet List
B2: Item | C2: Input
B4: Academic Year | C4: 2026-27 | E4: DO NOT MAKE ANY CHANGES IN THIS SHEET

Sheet Department Budget
A1: CHRIST (Deemed to be University)
A2: =CONCATENATE("DEPARTMENTAL FINANCIAL BUDGET - ",List!$C$4) -> DEPARTMENTAL FINANCIAL BUDGET - 2026-27
A3: DEPARTMENT: CSE | E3: =CONCATENATE("ACADEMIC YEAR - ",List!$C$4) -> ACADEMIC YEAR - 2026-27
A4: HOD: | B4: Dr M Balamurugan | E4: DEAN: | F4: Dr Raghunandhankumar
A6: EARNINGS (in Rs.): | C6: ='Revenue or Earnings'!E30 -> 5765000 | E6: REVENUE EXP (in Rs.): | G6: ='Revenue Expenditures'!F72 -> 31138700
E7: CAPITAL EXP (in Rs.): | G7: =CAPEX!D27 -> 19720000
A8: TOTAL EARNINGS | C8: =C6 -> 5765000 | E8: TOTAL EXPENDITURE | G8: =G6+G7 -> 50858700
E9: SURPLUS / (DEFICIT) | G9: =C8-G8 -> -45093700
A12: DATE:
A13: HOD | C13: DEAN | F13: CFO
A15: Note:
A16: 1. The above statement is the Consolidated Budget for the department which will indicate Budgeted Income & Expenses.
A17: 2. DO NOT input any values in this worksheet. All inputs should be provided in subsequent worksheets.
A18: 3. As all the values are formula driven, please cross verify the balances appearing above with the corresponding
A19: workings to ensure the accuracy of this Budget statement.
A20: 4. Only provide inputs for Department, HOD and Dean above highlighted.
A21: 5. DO NOT merge/delete any worksheets. Each worksheet should be populated individually and the balances from those
A22: worksheets will be brought above with the help of formulas set above. Additionally, no formulas should be added.
A23: 6. In case if any particular worksheet is not applicable or we do not have either revenue and/or expenses, DO NOT
A24: delete the respective worksheet, please leave the respective worksheet as blank.

Sheet Revenue or Earnings
A1: CHRIST (Deemed to be University)
A2: =CONCATENATE("DEPARTMENTAL REVENUE BUDGET - ",List!$C$4) -> DEPARTMENTAL REVENUE BUDGET - 2026-27
A3: DEPARTMENT: | C3: Computer Science and Engineering | F3: =CONCATENATE("ACADEMIC YEAR - ",List!$C$4) -> ACADEMIC YEAR - 2026-27
A4: HOD: | B4: Dr M Balamurugan | F4: DEAN: Dr Raghunandhankumar
A6: SL NO. | B6: EARNINGS | C6: Comments | D6: SOURCE | E6: AMOUNT | F6: BASIS OF BUDGET (Refer Note 2) | H6: PREVIOUS YEAR
H7: BUDGET | I7: ACTUAL
A8: 1 | B8: External Projects | C8: This is the total funds sanctioned from external agencies to all the faculties of the department. | D8: Through funding Agencies such as DST, DBT, AICTE etc | E8: 2500000 | F8: Department has applied 15 projects to various external funding agencies and awaiting for the results
A9: =A8+1 -> 2 | B9: Consultancy | C9: This is the amount estimated to be earned through consulatncy projects | D9: Through industrial consultancy projects | E9: 1000000 | F9: 1 Consultancy project has been processed and sanctioned
B10: (mention separately)
A11: =A9+1 -> 3 | B11: Training | C11: This is the amount estimated to be earned through conduct of various training programmes | D11: Registration Fees
B12: (mention separately)
A13: =A11+1 -> 4 | B13: Fests | C13: This is total income earned through various fest of the department. Kindly mention the income earned from fest separately. Example: If the department/ Centre has 7 events, then there should be 7 rows and each row the respective event income has to be mentioned and the budget for that event has to be mentioned separately.
B14: (mention separately, if more than one)
C15: Departments have to price the registration fee which covers the cost of providing Kits, Lunch and Snacks at the minimum. This should be the minimum fee and department is free to charge more. | D15: Registration Fees
C16: Department have to ensure that for internal fests and events, atleast 50% of the cost of the fest and event has to be raised through Sponsorships. In case of extenral events, workshops, seminars etc, the event has to be 100% sourced through Sponsoships. | D16: Sponsorships
D17: Others
A18: =A13+1 -> 5 | B18: Seminars / Workshops / Conference / Events | C18: This is the amount estimated to be earned through conduct of various Seminars/ Workshops/Conference/ Events | D18: Registration Fees | E18: 200000
B19: (mention separately, if more than one) | C19: International Conference | D19: 100000
C20: FDPs | D20: 50000
C21: Workshops | D21: 50000
D22: Sponsorships
D23: Others
A24: =A18+1 -> 6 | B24: Value Added Courses / Specialisations | C24: This is the amount estimated to be earned through conduct of various value added courses | D24: Registration Fees | E24: 150000
B25: (mention separately, if more than one) | C25: Certifications Courses (no of courses and no of students will be decided once department gets input from students), As of now, approximately 10 courses can be offered to 150 stduents @ the cost of Rs 1000 each student
A26: =A24+1 -> 7 | B26: Child Sponsorships | C26: This is the amount that the department is set to raise as Child Sponsorship from students. Kindly note that this should be collected from students who are ready to contribute to the cause. It should not be made mandatory to all students. (No. of students in the department X Rs. 500) | D26: Approx 500 x 500 | E26: 25000
A27: =A26+1 -> 8 | B27: Gold Medal Sponsorship | C27: Departments are encouraged to provide students with gold medals for their outstanding academic performances. Kindly note that these gold medals will be full sourced from sponsorships raised by the departments from external organisations or individuals. | E27: 450000
A28: 9 | B28: Honors Course | C28: Department is offering honors courses in Cyber Security & Quantum Computing domains. 2nd Year : 130 x 4000 = 520000 3rd Year : 130 x 4000 = 520000 3rd Year : 100 x 4000 = 400000 (Cyber Security Project) | E28: 1440000
A30: TOTAL EARNINGS | E30: =SUM(E8:E29) -> 5765000 | H30: =SUM(H8:H29) -> 0 | I30: =SUM(I8:I29) -> 0
A33: DATE:
A34: HOD | D34: DEAN | G34: CFO
A36: Note:
A37: 1. In case of multiple Fests/Seminars/Workshops/Conferences/Events/Value Added Courses or Specialisation, please ensure that
A38: each Fest/Seminar/Workshop etc is given above separately by adding additional lines under the respective categories.
A39: 2. Provide a brief about the underline assumption used for the respective Budget number. (For example: In case any revenue is already
A40: agreed either through no of registrations or fixed revenue agreed to be received, please mention "No. of Registrations" or "Fixed
A41: Revenue agreed" respectively under Basis of Budget.)
A42: 3. In case a particular category has multiple revenue and/or expenses, please prepare a separate worksheet and link the revenue total from
A43: the worksheet above.
A44: 4. The earnings mentioned above should be matching with the "Fests and Other Events" worksheet that is created for each such category.
A45: 5. The cells highlighted in Orange are SUM formulas. Please check the accuracy of such totals after completing the working. Ensure that
...

Sheet Revenue Expenditures
A1: CHRIST (Deemed to be University)
A2: =CONCATENATE("DEPARTMENTAL REVENUE EXP BUDGET - ",List!$C$4) -> DEPARTMENTAL REVENUE EXP BUDGET - 2026-27
A3: DEPARTMENT: | C3: Computer Science and Engineering | G3: =CONCATENATE("ACADEMIC YEAR - ",List!C4) -> ACADEMIC YEAR - 2026-27
A4: SL NO. | B4: REVENUE EXP: ITEMS | C4: Comments | D4: QTY. (Nos./hrs) | E4: RATE (per unit/per hour) | F4: AMOUNT BUDGETED (INLC. OF GST) | G4: JUSTIFICATION OF NEED* | H4: BASIS OF BUDGET (Refer note 1) | J4: PREVIOUS YEAR
J5: BUDGET | K5: ACTUAL
B6: External Remuneration
A7: 1 | B7: Adjunct Faculty Honorarium (Refer note 2) | C7: No of hours per faculty per subject X No. of subjects X No. of faculties X No. of Semester/Trimester X Per houre rate | D7: 6 | E7: 65000 / Month | F7: 4680000
A8: =A7+1 -> 2 | B8: Guest Lectures | C8: No of hours per guest per subject X No. of guest lectures X No. of guest X No. of Semester/Trimester X Per houre rate | D8: 10 | E8: 2500 | F8: 25000 | G8: For Delivering Expert Sessions | H8: based on the remuneration guidelines given by university | J8: 22500
A9: =A8+1 -> 3 | B9: Guest Relation | C9: No of hours per guest per event X No. of guest events X No. of guest X No. of Semester/Trimester X Per houre rate | D9: 10 | E9: 2500 | F9: 25000
A10: 4 | B10: Remenuration to Contract Employees | C10: Amount payable for the entire year for 1 person X No. of contract staff
A11: 5 | B11: Remenuration to Interns | C11: Amount payable for the entire year for 1 person X No. of interns
A12: 6 | B12: Remenuration to Consultants | C12: Amount payable for the entire year for 1 person X No. of Consultants | D12: 2 Persons | E12: 2000 / student | F12: 1600000 | G12: to handle honors course with industry exposure Approx 200 x 2000x4
A13: 7 | B13: Project Viva | D13: 15 | E13: 5000 | F13: 75000 | G13: 15 Faculty Members as External Examiners from other Institutions (approx Rs 5000 / faculty) | J13: 0
A14: 8 | B14: Professor in Practice | D14: 1 | E14: 125000 | F14: 125000
B19: Staff Development & Welfare
A20: 9 | B20: Faculty Development Programme | C20: No. of faculties to be sent for FDP X Amount to be spent per FDP (Average) | D20: 40 | E20: 10000 | F20: 400000 | G20: Price is equivalent to market value
A21: =A20+1 -> 10 | B21: Seminar | C21: No. of faculties to be sent for Seminars X Amount to be spent per Seminar (Average) | D21: 15 | E21: 5000 | F21: 75000 | G21: Price is equivalent to market value
A22: =A21+1 -> 11 | B22: Workshops | C22: No. of faculties to be sent for Workshops X Amount to be spent per Workshop (Average) | D22: 20 | E22: 5000 | F22: 100000 | G22: Price is equivalent to market value
A23: =A22+1 -> 12 | B23: Conference | C23: No. of faculties to be sent for Conference X Amount to be spent per Conference (Average) | D23: 40 | E23: 10000 | F23: 400000 | G23: As per university guidelines
A24: =A23+1 -> 13 | B24: Membership Reimbursement | C24: No. of faculties in the department X Rs. 5,000 | D24: 40 | E24: 5000 | F24: 200000 | G24: As per university guidelines
A25: =A24+1 -> 14 | B25: Travel & Conveyance - Conveyance | C25: No. of faculties who will be travelling via cabs, autos, metro etc X Amount of Conveyance | F25: 400000 | G25: 40 faculty Members @ Rs 10000 for Industry Visits to Lab setup / Field Visit / Best Practice Visits
A26: =A25+1 -> 15 | B26: Travel & Conveyance - Domestic Travel | C26: No. of faculties travelling Domestic via bus, train, flights X No. of trip (both ways) X Cost per trip | F26: 200000 | G26: 20 Faculty Members @Rs 10000
A27: =A26+1 -> 16 | B27: Travel & Conveyance - International Travel | C27: No. of faculties travelling Internation via flights X No. of trip (both ways) X Cost per trip | F27: 200000 | G27: For International Visits : 5 Faculty Members x Rs.2,00,000
A28: 40 | B28: Faculty Training in Industry | D28: 40 | E28: 7000 | F28: =D28*E28 -> 280000 | G28: 44 Faculty Members x Rs.7000 as Training Cost
A29: 16 | B29: Out Bound Training | D29: 40 | E29: 4500 | F29: =D29*E29 -> 180000 | G29: 44 Faculty Members x Rs.4,500
A30: 17 | B30: Remuneration for Instructors for conducting Certification Courses | D30: 6 | E30: 25000 | F30: =D30*E30 -> 150000 | G30: 06 Faculty Members x Rs.25000 (handling course for Full year) Approx
B31: Student Related Expenses
A32: =A27+1 -> 17 | B32: Fests/Seminars / Workshops / Events #(Specify) (Refer note 3) | C32: Each Fest/ Seminar/ Workshop or any other Event has to be separately budgeted considering the various activities under each of them. Each Fest, Seminar, Workshop and other event has to be mentioned separately. Example: If the department/ Centre has 7 events, then there should be 7 rows and each row the respective event has to be mentioned and the budget for that event has to be mentioned separately. | F32: 2261000
B33: (mention separately the list of Fests/ Seminars/ Workshops/ Events, if it is more than one)
A34: =A32+1 -> 18 | B34: Fee Concession | C34: This will be a total of the following: - Identify 2 (two) students to be given full fee concessions per course X No of courses in the department X Fee for the year - Identify 3 (three) students to be give part fee concessions percourse X No of courses in the department X 50% X Fee for the year | F34: 4200000 | G34: 2 Students x 4 Courses x 300000 3 Students x 4 Courses x 150000
A35: =A34+1 -> 19 | B35: Scholarships | C35: This will be a total of the following: - Identify 2 (two) students to be given full scholarship per course X No of courses in the department X Fee for the year for the respective courses - Identify 3 (three) students to be give part scholarship per course X No of courses in the department X 50% X Fee for the year for the respective courses | F35: 4200000 | G35: 2 Students x 4 Courses x 300000 3 Students x 4 Courses x 150000
A36: =A35+1 -> 20 | B36: Contribution for Social Cause (Student Sensitization) | C36: This pertains to the amount which will be spent for taking students for social sentisation to various sites | F36: 100000
A37: =A36+1 -> 21 | B37: Charges for Training students Placement Training for 2nd year & 3 rd Year students | C37: This pertains to the various external trainings which will be given to students. A separate list of all such trainings have to be provided along with the budget for each training | D37: 500 | E37: 2000 | F37: 1000000 | G37: For Placement Training based on the agreeement with vendor
B38: (mention separately the list of training to students, if it is more than one)
A39: =A37+1 -> 22 | B39: Inauguration Expenses | C39: In case the department is having any inauguration for any course, labs, clubs, cells etcs, the total expense on inauguration has to be budget. (No. of inaugurations planned X Amount spent per inauguration) | F39: 50000 | G39: Inauguration of ASCII Inauguration
B40: (mention separately the list of inauguration planned, if it is more than one)
A41: =A39+1 -> 23 | B41: Exhibitions | C41: If the department is conducting various exhibitions then amount shoulod be budgeted for the same. (No. of exhibitions planned X Amount spent per exhibition) | D41: 2 | E41: 50000 | F41: 100000 | G41: 1 Project Exhibition & 1 Hackathon
B42: (mention separately the list of exhibitions planned, if it is more than one)
A43: =A41+1 -> 24 | B43: Expenses for the Clubs / Cells | C43: Each club and cells has to be mentioned separately and budgeted for that. | G43: Included in Sl. No 15
B44: (mention separately the list of exhibitions planned, if it is more than one)
...

Sheet CAPEX
A1: CHRIST (Deemed to be University)
A2: =CONCATENATE("DEPARTMENTAL CAPEX BUDGET - ",List!$C$4) -> DEPARTMENTAL CAPEX BUDGET - 2026-27
A3: DEPARTMENT: Computer Science and Engineering | F3: =CONCATENATE("ACADEMIC YEAR - ",List!C4) -> ACADEMIC YEAR - 2026-27
A4: HOD: | B4: Dr M Balamurugan | F4: DEAN: Dr Raghunandhankumar
A5: SL NO. | B5: CAPEX: ITEMS @ (BUDGET) | C5: QTY | D5: APPROX. COST (INC. OF GST) | E5: EXISTING STOCK | F5: JUSTIFICATION OF NEED* | G5: BASIS OF BUDGET (Refer note 1) | I5: PREVIOUS YEAR
I6: BUDGET | J6: ACTUAL
A7: 1 | B7: Canva Team Subscription | C7: 1 | D7: 10000
A8: =A7+1 -> 2 | B8: 05 GPU Computers (( Computer System i7 14th Gen 8471 PROCESSOR GIGABYTE MOTHERBOARD B760MH DDR5 ZOTAK RTX5060 8GB GRAPHICS CARD 1TB NVME SSD CRUCIAL 32GB DDR5 G SKILL 5200MHZ RAM LOGITECH MK200 K/B+ MOUSE COOLER MASTER CABINET 310C COOLER MASTER 550WATTS SMPS LG 24'' MONITOR 24MR400 ) | C8: 5 | D8: 800000 | F8: To Support for Research Activities
A9: 3 | B9: Cyber Security Lab Computers ( Computer System i7 14th Gen 8471 PROCESSOR GIGABYTE MOTHERBOARD B760MH DDR5 ZOTAK RTX 4 series 4GB GRAPHICS CARD 480 NVME SSD CRUCIAL 32GB DDR5 G SKILL 5200MHZ RAM LOGITECH MK200 K/B+ MOUSE COOLER MASTER CABINET 310C COOLER MASTER 550WATTS SMPS LG 24'' MONITOR 24MR400 ) | C9: 60 | D9: 7800000 | F9: Establishing Lab for newly introduced programme
A10: 4 | B10: 100 users subscription - Firewall (any company) . | C10: 1 | D10: 200000
A11: 5 | B11: DELL VM Server _ Dell PowerEdge R550 Rack Server. | C11: 1 | D11: 510000
A12: 6 | B12: Cyber Security Lab Furnuiters & Networking Components | C12: 1 | D12: 8000000
A13: 7 | B13: Microsoft Purview DLP - Cloud EndPoint Security + Security Onion - NDR + SIEM + IDS. | C13: 1 | D13: 500000
A14: 8 | B14: Encase Forensics Suit | C14: 1 | D14: 800000
A15: 9 | B15: IOT Lab Components
B16: Quadcopter - assembly | C16: 1 | D16: 15000
B17: Humanoid bot | C17: 1 | D17: 20000
B18: RFID NFC Reader Writer USB ER302 SDK Software E Reader V6.0 & RFID card (pack of 25) | C18: 1 | D18: 5000
B19: C-DAC IOT Controller Module | C19: 10 | D19: 160000
B20: IOT Academic Lab Components & Sensors | C20: 50 | D20: 800000
B21: Advantech - Think Alive Industry Oriented Lab Components | C21: 2 | D21: 100000
A27: TOTAL CAPEX | D27: =SUM(D7:D26) -> 19720000 | I27: =SUM(I7:I26) -> 0 | J27: =SUM(J7:J26) -> 0
A30: DATE: | C30: HOD | G30: DEAN
A32: Note:
A33: 1. Provide a brief about the underline assumption used for the respective Budget number. (For example: In case where the expense is already negotiated
A34: with the Vendor, please mention "Price negotiated with the Vendor" or in case where expense is estimated using market value of similar items,
A35: please mention "Price is equivalent to Market Value" and so on under Basis of Budget)
A36: 2. Items which are in the nature of capital/investment where the usage is for period(s) more than a year should be mentioned above.
A37: 3. In case of additional items, add additional lines as needed.
A38: 4. The cells highlighted in Orange are SUM formulas. Please check the accuracy of such totals after completing the working. Ensure that the total computed
A39: in those cells are capturing the entire total and is 100% complete and accurate.
A40: 5. In case where this worksheet is not applicable or the department does not have any capital expenditure, DO NOT delete this worksheet.
A41: Leave this worksheet as blank.
A42: 6. GST should also be included & considered in the Budget expense numbers above. In case of confusion on the rates applicable, refer the below link
A43: https://cbic-gst.gov.in/gst-goods-services-rates.html
A44: 7. This budget must be submitted to the CHIEF FINANCE OFFICER / ASSITANT FINANCE OFFICER by 31.12.2023 , duly recommended by the DEAN / Directors

Sheet man power
A1: Christ University, Bangalore
A2: Departmental workload statement for the year 2015-2016
A3: Department: | F3: Semester: Odd /Even:
A4: Course/Paper | B4: No. of Students | C4: Theory workload | D4: Practical workload | G4: Any Other (Specify) | H4: Total Hrs/Wk | I4: Remarks (if any)
D5: Batches | E5: Hours | F5: Total
C20: S×P×H= | E20: B×H×T=
A21: Total
A22: Note:
B23: No. of sections´No. of papers ´ No. of hours = Total theory workload
B24: No. of batches´No. of hours ´ No. of teachers = Total practical workload (2 practicals = 1 Theory)
B25: Submit the odd and even semester workload separately, if it affects the man power requirements.
A27: Position | C27: No. of Positions | F27: No. of Personnel
C28: Approved | D28: New | E28: Total* | F28: Existing | G28: Required | H28: Remarks/ Reason
A29: Teaching (Regular)
A30: Teaching (Guest)
A31: Admin. Staff
A32: Support Staff
A33: *Approved + New = Total = existing + Required
A35: Signature of the Head of the Department/Center:
A37: Recommendation of the Dean/director:
A39: Signature:
A40: Remarks by Personnel Officer:
A42: Approval by CFO:

Sheet Fest and Other Events
A1: CHRIST (Deemed to be University)
A2: FEST/ SEMINARS, WORKSHOPS, EVENTS & MEETINGS
A3: Department | C3: Computer Science and Engineering
A5: Nature of Program / Event (Date) | C5: National Seminar, International Conference, Workshops and ASCII activities
A8: Details of Income to be generated
A9: SL NO. | B9: CATEGORIES | G9: NO. OF PARTICIPANTS | H9: RATE | I9: AMOUNT (in RS.)
A10: 1 | B10: Participation Fee
A11: 2 | B11: Sponsorship | E11: CSI / IEEE | G11: 200 | H11: 250 | I11: =G11*H11 -> 50000
A12: 3 | B12: Others | G12: 85 | H12: 2500 | I12: =G12*H12 -> 212500
A15: TOTAL INCOME | I15: =SUM(I10:I14) -> 262500
A17: Details of Expenses to be incurred (inclusive of GST)
A18: SL NO. | B18: PARTICULARS | G18: QTY | H18: RATE | I18: AMOUNT (in RS.)
A19: 1 | B19: Workshop on Emerging Trends | G19: 20 | H19: 10000 | I19: =G19*H19 -> 200000
A20: =A19+1 -> 2 | B20: Conferences | G20: 1 | H20: 500000 | I20: =G20*H20 -> 500000
A21: =A20+1 -> 3 | B21: ASCII Peer Events & Foobar Fest | G21: 50 | H21: 10000 | I21: =G21*H21 -> 500000
A22: =A21+1 -> 4 | B22: Seminar on Industry Practises | G22: 5 | H22: 10000 | I22: =G22*H22 -> 50000
A23: =A22+1 -> 5 | B23: Sports Day (Tableau) | G23: 1 | H23: 20000 | I23: =G23*H23 -> 20000
A24: =A23+1 -> 6 | B24: IEEE / ACM Student Branch Events | G24: 10 | H24: 10000 | I24: =G24*H24 -> 100000
A25: =A24+1 -> 7 | B25: CSA | G25: 4 | H25: 10000 | I25: =G25*H25 -> 40000
A26: =A25+1 -> 8 | B26: Experience Engineering Programme | G26: 1 | H26: 15000 | I26: =G26*H26 -> 15000
A27: =A26+1 -> 9 | B27: Magnovite | G27: 1 | H27: 300000 | I27: 300000
A28: =A27+1 -> 10 | B28: ICETech | G28: 1 | H28: 50000 | I28: =G28*H28 -> 50000
A29: =A28+1 -> 11 | B29: Blossoms | G29: 1 | H29: 20000 | I29: =G29*H29 -> 20000
A30: =A29+1 -> 12 | B30: Daksh | G30: 1 | H30: 25000 | I30: =G30*H30 -> 25000
A31: =A30+1 -> 13 | B31: Ideathon - Projects _ State wide | G31: 1 | H31: 100000 | I31: =G31*H31 -> 100000
A32: =A31+1 -> 14 | B32: Tech Utsav | G32: 2 | H32: 50000 | I32: =G32*H32 -> 100000
A33: =A32+1 -> 15 | B33: SDG Cell Activities | G33: 5 | H33: 3000 | I33: =G33*H33 -> 15000
A34: =A33+1 -> 16 | B34: Research Colloquium | G34: 1 | H34: 30000 | I34: =G34*H34 -> 30000
A35: =A34+1 -> 17 | B35: Research Seminar | G35: 1 | H35: 20000 | I35: =G35*H35 -> 20000
A36: =A35+1 -> 18 | B36: Prizes for 'participate and win contests' - News Letter & Magzine | G36: 5 | H36: 200 | I36: =G36*H36 -> 1000
A37: =A36+1 -> 19 | B37: III Cell Related events | G37: 10 | H37: 15000 | I37: =G37*H37 -> 150000
A38: =A37+1 -> 20 | B38: Entruperenuership Event | G38: 5 | H38: 5000 | I38: =G38*H38 -> 25000
I39: =G39*H39 -> 0
A40: TOTAL EXPENDITURE | I40: =SUM(I19:I39) -> 2261000
